Workbook
Name CompsWeight: Assumptions!$B$10
Name DCFWeight: Assumptions!$B$9
Name DilutedShares: Assumptions!$B$27
Name FY2025AdjEBITDA: Assumptions!$B$24
Name MinorityInterests: Assumptions!$B$26
Name NetDebtToEBITDA: Assumptions!$B$25
Name PrimaryWACC: Assumptions!$B$7
Name SelectedScenario: Assumptions!$B$5
Name TerminalGrowth: Assumptions!$B$8

Sheet Cover
A1: SES S.A. — Company Valuation
A3: DCF & Comparable Company Analysis | Internal Investment Note
A5: TARGET | B5: SES S.A. (Euronext Paris / Luxembourg Stock Exchange) | E5: TICKER | F5: SESG
A6: PREPARED BY | B6: Joy Lorna | E6: AS OF DATE | F6: 46253
A7: ROLE / LANE | B7: Financial Analyst | Corporate Finance | Investment Analysis
A8: MODEL STATUS | B8: Educational portfolio model | Formula audit passed 19 Aug 2026 | Source-backed actuals with clearly identified illustrative market inputs
A10: PROJECT OBJECTIVE | B10: Value a European mid-cap listed company using a five-year FCFF DCF and a five-peer comparable-company analysis. The model is designed as a decision-oriented internal investment note, with a defensible fair value range, a directional view, and transparent assumptions rather than false precision.
A13: DATA INTEGRITY | B13: FY2024–FY2025 revenue and Adjusted EBITDA, FY2025 leverage, FY2026 stable outlook, the Intelsat closing date, listing details, FY2025 minority interests, and the latest economic-equivalent share count are source-based. Beta, credit spread, peer multiples, and the current market price remain market-sensitive inputs requiring refresh before any live investment decision.
A16: WORKBOOK CONTENTS
A17: Exec_Summary | B17: One-page investment memo with valuation conclusion, thesis, and risks.
A18: Assumptions | B18: Scenario control and all editable operating and valuation drivers.
A19: Data_Raw | B19: Source-backed historical inputs and source references; source rows are not edited.
A20: Historicals | B20: Clean three-year actuals, trend diagnostics, and analytical commentary.
A21: Projections | B21: Five-year operating forecast and FCFF build for FY2026E–FY2030E.
A22: WACC | B22: Bottom-up beta, CAPM cost of equity, cost of debt, and target capital structure.
A23: DCF | B23: Explicit FCFF discounting, Gordon Growth terminal value, and equity bridge.
A24: Sensitivity | B24: Two-variable enterprise-value analysis across WACC and terminal growth.
A25: Comps | B25: Five-peer EV/EBITDA and P/E framework with implied valuation ranges.
A26: Football_Field | B26: Reconciliation of DCF, comps, and blended valuation ranges.
A27: Charts | B27: Presentation-ready operating and valuation visuals.
A28: Sources | B28: Source register, URLs, and notes distinguishing sourced data from judgement.
A30: IMPORTANT — EDUCATIONAL USE ONLY. This workbook is not investment advice. Market inputs identified as illustrative must be refreshed and independently verified before use in any real investment decision.

Sheet Exec_Summary
A1: SES S.A. — Executive Investment Summary
A2: ="Internal valuation note | Selected "&Assumptions!B5&" case | Prepared by Joy Lorna | Model outputs as of 19 August 2026" -> Internal valuation note | Selected Base case | Prepared by Joy Lorna | Model outputs as of 19 August 2026
A4: INVESTMENT VIEW
A5: DIRECTIONAL VIEW | C5: BLENDED FAIR VALUE | E5: BLENDED ENTERPRISE VALUE | G5: BASE DCF VALUE
A6: ="WATCHLIST / CONDITIONAL ACCUMULATE BELOW "&TEXT(Football_Field!B36,"€0.00") -> WATCHLIST / CONDITIONAL ACCUMULATE BELOW €8.85 | C6: =TEXT(Football_Field!B36,"€0.00")&"–"&TEXT(Football_Field!C36,"€0.00")&" / share" -> €8.85–€17.51 / share | E6: ="€"&TEXT(Football_Field!B8/1000,"0.0")&"bn–€"&TEXT(Football_Field!C8/1000,"0.0")&"bn" -> €8.4bn–€12.1bn | G6: =TEXT(DCF!B14,"€0.00")&" / share" -> €16.78 / share
A10: BUSINESS SUMMARY & RECOMMENDATION RATIONALE
A11: ="SES is a Luxembourg-headquartered satellite and connectivity operator whose acquisition of Intelsat on 17 July 2025 materially changed its scale, leverage, and execution risk. The "&Assumptions!B5&" case assumes FY2026 revenue growth of "&TEXT(Projections!B7,"0.0%")&", gradual EBITDA-margin recovery from "&TEXT(Projections!B9,"0.0%")&" to "&TEXT(Projections!F9,"0.0%")&_xlfn._LONGTEXT(", and declining capital intensity. The DCF supports a higher valuation than public-market peers, while the comps framework embeds a larger discount for leverage, integration risk, structural Media pressure, and LEO competition. Accordingly, the model supp","orts a WATCHLIST / CONDITIONAL ACCUMULATE stance below the €")&TEXT(Football_Field!B36,"0.00")&" lower fair-value threshold—not an unconditional buy call—until the current share price and live peer multiples are refreshed." -> SES is a Luxembourg-headquartered satellite and connectivity operator whose acquisition of Intelsat on 17 July 2025 materially changed its scale, leverage, and execution risk. The Base case assumes FY2026 revenue growth of 0.0%, gradual EBITDA-margin recovery from 45.5% to 49.0%, and declining capital intensity. The DCF supports a higher valuation than public-market peers, while the comps framework embeds a larger discount for leverage, integration risk, structural Media pressure, and LEO competition. Accordingly, the model supports a WATCHLIST / CONDITIONAL ACCUMULATE stance below the €8.85 lower fair-value threshold—not an unconditional buy call—until the current share price and live peer multiples are refreshed.
A16: VALUATION SNAPSHOT
A17: Method | B17: Low | C17: High | D17: Interpretation
A18: DCF sensitivity | B18: =Football_Field!B6 -> 10091.447 | C18: =Football_Field!C6 -> 14116.906 | D18: Fundamentals-based range; highly sensitive to WACC and terminal growth.
A19: Comps EV / EBITDA | B19: =Football_Field!B7 -> 5976.425 | C19: =Football_Field!C7 -> 8964.6375 | D19: Public-market cross-check using illustrative 5.0x–7.5x multiples.
A20: Blended enterprise value | B20: =Football_Field!B8 -> 8445.4382 | C20: =Football_Field!C8 -> 12055.998 | D20: =TEXT(Assumptions!B9,"0%")&" DCF / "&TEXT(Assumptions!B10,"0%")&" Comps reconciliation." -> 60% DCF / 40% Comps reconciliation.
A21: Indicative value per share | B21: =Football_Field!B36 -> 8.8488805 | C21: =Football_Field!C36 -> 17.507169 | D21: Per-share range uses reported minority interests and the official economic-equivalent share count.
A22: Current market reference | B22: Not refreshed | C22: Not refreshed | D22: No validated live share price or market EV is included; recommendation remains conditional.
A24: KEY INVESTMENT FINDINGS
A25: ="1. Growth quality: Revenue increases from €"&TEXT(Projections!B6,"#,##0")&"m in FY2026E to €"&TEXT(Projections!F6,"#,##0")&"m in FY2030E, a "&TEXT((Projections!F6/Projections!B6)^(1/4)-1,"0.0%")&" CAGR." -> 1. Growth quality: Revenue increases from €2,627m in FY2026E to €2,857m in FY2030E, a 2.1% CAGR.
A26: ="2. Margin recovery: Adjusted EBITDA grows at "&TEXT((Projections!F8/Projections!B8)^(1/4)-1,"0.0%")&" CAGR as the margin recovers by "&TEXT(Projections!F9-Projections!B9,"0.0%")&" to "&TEXT(Projections!F9,"0.0%")&", still below the FY2024 standalone level." -> 2. Margin recovery: Adjusted EBITDA grows at 4.0% CAGR as the margin recovers by 3.5% to 49.0%, still below the FY2024 standalone level.
A27: ="3. Cash conversion: FCFF rises from €"&TEXT(Projections!B18,"#,##0")&"m to €"&TEXT(Projections!F18,"#,##0")&"m as CapEx intensity declines from "&TEXT(-Projections!B16/Projections!B6,"0.0%")&" to "&TEXT(-Projections!F16/Projections!F6,"0.0%")&"." -> 3. Cash conversion: FCFF rises from €366m to €748m as CapEx intensity declines from 26.4% to 16.0%.
A28: ="4. Valuation risk: Terminal value represents "&TEXT(DCF!B31,"0.0%")&" of DCF enterprise value, while the comps range remains materially below DCF; sensitivity and triangulation are therefore essential." -> 4. Valuation risk: Terminal value represents 80.0% of DCF enterprise value, while the comps range remains materially below DCF; sensitivity and triangulation are therefore essential.
A30: UPSIDE CATALYSTS | E30: DOWNSIDE RISKS
A31: • Faster Intelsat integration and synergy delivery • Sustained Government, mobility, and aviation growth • Sovereign connectivity contract wins • Deleveraging toward investment-grade metrics • Earlier CapEx normalisation and stronger cash returns | E31: • Slower deleveraging or weaker cash conversion • Accelerating Media revenue erosion • LEO constellation pricing and capacity pressure • Integration, restructuring, or execution slippage • Satellite launch, deployment, or in-orbit health risk
A37: DATA INTEGRITY & NEXT ACTION
A38: =_xlfn._LONGTEXT("Source-backed: FY2023–FY2025 revenue and Adjusted EBITDA, FY2025 leverage, FY2026 stable outlook, Intelsat closing date, listing details, reported minority interests, and economic-equivalent shares. Illustrative / refresh required: beta inputs, credit spr","ead, peer multiples, and current market price. Before using this as a live investment recommendation, refresh those market-sensitive items from Bloomberg, Capital IQ, FactSet, company filings, or broker data, then compare the validated market price with t","he €")&TEXT(Football_Field!B36,"0.00")&_xlfn.UNICHAR(8211)&"€"&TEXT(Football_Field!C36,"0.00")&" model range." -> Source-backed: FY2023–FY2025 revenue and Adjusted EBITDA, FY2025 leverage, FY2026 stable outlook, Intelsat closing date, listing details, reported minority interests, and economic-equivalent shares. Illustrative / refresh required: beta inputs, credit spread, peer multiples, and current market price. Before using this as a live investment recommendation, refresh those market-sensitive items from Bloomberg, Capital IQ, FactSet, company filings, or broker data, then compare the validated market price with the €8.85–€17.51 model range.
A43: Model conclusion: SES offers meaningful integration and cash-conversion optionality, but leverage and execution risk justify a conditional—not unconditional—positive stance.
A46: VALUATION LIMITATIONS
A47: ="• Peer multiples are snapshot market-based measures."&CHAR(10)&"• DCF is highly sensitive to WACC and terminal growth."&CHAR(10)&"• Terminal value contributes approximately "&TEXT(DCF!B31,"0%")&" of EV."&CHAR(10)&"• SES remains in a post-Intelsat integration period."&CHAR(10)&"• Valuation outputs should be interpreted as a range, not a precise estimate." -> • Peer multiples are snapshot market-based measures. • DCF is highly sensitive to WACC and terminal growth. • Terminal value contributes approximately 80% of EV. • SES remains in a post-Intelsat integration period. • Valuation outputs should be interpreted as a range, not a precise estimate.

Sheet Assumptions
A1: Assumptions & Scenario Control
A2: Central model inputs | Blue = hardcoded input • Black = formula • Green = source-linked value
A4: SCENARIO CONTROL
A5: Selected scenario | B5: Base | C5: Choose Base, Upside, or Downside; forecast and DCF inputs update automatically.
A6: Model currency | B6: EUR millions | C6: All financial statements and valuation outputs, except per-share values and multiples.
A7: Primary valuation WACC | B7: =INDEX($B$32:$B$34,MATCH($B$5,$A$32:$A$34,0)) -> 0.072 | C7: Selected-case discount rate used by the primary DCF.
A8: Terminal growth rate | B8: =INDEX($C$32:$C$34,MATCH($B$5,$A$32:$A$34,0)) -> 0.015 | C8: Selected-case long-term nominal growth rate for EUR FCFF.
A9: Blended DCF weight | B9: 0.6 | C9: Methodology weight applied to the DCF valuation range.
A10: Blended Comps weight | B10: 0.4 | C10: Methodology weight applied to the comparable-company range; weights must total 100%.
A13: SELECTED-CASE PROJECTION DRIVERS
A14: Driver | B14: FY2026E | C14: FY2027E | D14: FY2028E | E14: FY2029E | F14: FY2030E | G14: Investment rationale
A15: Revenue growth % | B15: =SUMIFS($C$39:$C$56,$A$39:$A$56,$B$5,$B$39:$B$56,$A15) -> 0 | C15: =SUMIFS($D$39:$D$56,$A$39:$A$56,$B$5,$B$39:$B$56,$A15) -> 0.015 | D15: =SUMIFS($E$39:$E$56,$A$39:$A$56,$B$5,$B$39:$B$56,$A15) -> 0.02 | E15: =SUMIFS($F$39:$F$56,$A$39:$A$56,$B$5,$B$39:$B$56,$A15) -> 0.025 | F15: =SUMIFS($G$39:$G$56,$A$39:$A$56,$B$5,$B$39:$B$56,$A15) -> 0.025 | G15: FY2026 follows management’s stable year-on-year outlook; thereafter Networks growth offsets structural Media pressure.
A16: EBITDA margin % | B16: =SUMIFS($C$39:$C$56,$A$39:$A$56,$B$5,$B$39:$B$56,$A16) -> 0.455 | C16: =SUMIFS($D$39:$D$56,$A$39:$A$56,$B$5,$B$39:$B$56,$A16) -> 0.47 | D16: =SUMIFS($E$39:$E$56,$A$39:$A$56,$B$5,$B$39:$B$56,$A16) -> 0.48 | E16: =SUMIFS($F$39:$F$56,$A$39:$A$56,$B$5,$B$39:$B$56,$A16) -> 0.485 | F16: =SUMIFS($G$39:$G$56,$A$39:$A$56,$B$5,$B$39:$B$56,$A16) -> 0.49 | G16: Base case recovers toward, but remains below, the pre-merger standalone margin because the Intelsat mix remains dilutive.
A17: D&A (% revenue) | B17: =SUMIFS($C$39:$C$56,$A$39:$A$56,$B$5,$B$39:$B$56,$A17) -> 0.26 | C17: =SUMIFS($D$39:$D$56,$A$39:$A$56,$B$5,$B$39:$B$56,$A17) -> 0.25 | D17: =SUMIFS($E$39:$E$56,$A$39:$A$56,$B$5,$B$39:$B$56,$A17) -> 0.24 | E17: =SUMIFS($F$39:$F$56,$A$39:$A$56,$B$5,$B$39:$B$56,$A17) -> 0.23 | F17: =SUMIFS($G$39:$G$56,$A$39:$A$56,$B$5,$B$39:$B$56,$A17) -> 0.225 | G17: Elevated by the satellite asset base and acquisition accounting, then tapers as the purchase-price step-up amortises.
A18: CapEx (% revenue) | B18: =SUMIFS($C$39:$C$56,$A$39:$A$56,$B$5,$B$39:$B$56,$A18) -> 0.264 | C18: =SUMIFS($D$39:$D$56,$A$39:$A$56,$B$5,$B$39:$B$56,$A18) -> 0.22 | D18: =SUMIFS($E$39:$E$56,$A$39:$A$56,$B$5,$B$39:$B$56,$A18) -> 0.19 | E18: =SUMIFS($F$39:$F$56,$A$39:$A$56,$B$5,$B$39:$B$56,$A18) -> 0.17 | F18: =SUMIFS($G$39:$G$56,$A$39:$A$56,$B$5,$B$39:$B$56,$A18) -> 0.16 | G18: FY2026 remains investment-heavy for IRIS² and meoSphere; capital intensity normalises as major build phases mature.
A19: Change in NWC (% revenue) | B19: =SUMIFS($C$39:$C$56,$A$39:$A$56,$B$5,$B$39:$B$56,$A19) -> 0.005 | C19: =SUMIFS($D$39:$D$56,$A$39:$A$56,$B$5,$B$39:$B$56,$A19) -> 0.005 | D19: =SUMIFS($E$39:$E$56,$A$39:$A$56,$B$5,$B$39:$B$56,$A19) -> 0.005 | E19: =SUMIFS($F$39:$F$56,$A$39:$A$56,$B$5,$B$39:$B$56,$A19) -> 0.005 | F19: =SUMIFS($G$39:$G$56,$A$39:$A$56,$B$5,$B$39:$B$56,$A19) -> 0.005 | G19: A modest annual cash investment is applied consistently to reflect working-capital requirements.
A20: Tax rate | B20: =SUMIFS($C$39:$C$56,$A$39:$A$56,$B$5,$B$39:$B$56,$A20) -> 0.2387 | C20: =SUMIFS($D$39:$D$56,$A$39:$A$56,$B$5,$B$39:$B$56,$A20) -> 0.2387 | D20: =SUMIFS($E$39:$E$56,$A$39:$A$56,$B$5,$B$39:$B$56,$A20) -> 0.2387 | E20: =SUMIFS($F$39:$F$56,$A$39:$A$56,$B$5,$B$39:$B$56,$A20) -> 0.2387 | F20: =SUMIFS($G$39:$G$56,$A$39:$A$56,$B$5,$B$39:$B$56,$A20) -> 0.2387 | G20: Luxembourg City’s 2025+ combined corporate rate of 23.87% is used as a simplifying proxy; SES’s group effective rate spans jurisdictions.
A23: VALUATION BRIDGE INPUTS
A24: FY2025A Adjusted EBITDA | B24: =Data_Raw!D7 -> 1196 | C24: Source-linked from SES FY2025 results via Data_Raw.
A25: Adjusted net debt / EBITDA | B25: =Data_Raw!D9 -> 3.9 | C25: Source-linked FY2025 combined like-for-like leverage.
A26: Minority interests (reported) | B26: 91 | C26: Source-based: non-controlling interests reported in SES FY2025 Annual Report at 31 December 2025.
A27: Diluted economic-equivalent shares | B27: 417.00622 | C27: Source-based: 417.006m economic-equivalent shares from SES shareholder information at 30 June 2026; fully diluted EPS is not materially different from basic EPS.
A30: VALUATION SCENARIO LIBRARY — EDIT BLUE CELLS
A31: Scenario | B31: WACC | C31: Terminal growth | D31: Case interpretation
A32: Base | B32: 0.072 | C32: 0.015 | D32: Balanced execution case: stable FY2026, gradual margin recovery, and measured deleveraging.
A33: Upside | B33: 0.067 | C33: 0.02 | D33: Faster synergy capture and lower perceived risk support stronger cash conversion and a lower discount rate.
A34: Downside | B34: 0.077 | C34: 0.01 | D34: Slower integration, persistent Media pressure, and elevated leverage increase execution risk.
A37: OPERATING SCENARIO LIBRARY — EDIT BLUE CELLS
A38: Scenario | B38: Driver | C38: FY2026E | D38: FY2027E | E38: FY2028E | F38: FY2029E | G38: FY2030E
A39: Base | B39: Revenue growth % | C39: 0 | D39: 0.015 | E39: 0.02 | F39: 0.025 | G39: 0.025
A40: Base | B40: EBITDA margin % | C40: 0.455 | D40: 0.47 | E40: 0.48 | F40: 0.485 | G40: 0.49
A41: Base | B41: D&A (% revenue) | C41: 0.26 | D41: 0.25 | E41: 0.24 | F41: 0.23 | G41: 0.225
A42: Base | B42: CapEx (% revenue) | C42: 0.264 | D42: 0.22 | E42: 0.19 | F42: 0.17 | G42: 0.16
A43: Base | B43: Change in NWC (% revenue) | C43: 0.005 | D43: 0.005 | E43: 0.005 | F43: 0.005 | G43: 0.005
A44: Base | B44: Tax rate | C44: 0.2387 | D44: 0.2387 | E44: 0.2387 | F44: 0.2387 | G44: 0.2387
A45: Upside | B45: Revenue growth % | C45: 0.005 | D45: 0.025 | E45: 0.03 | F45: 0.03 | G45: 0.03
A46: Upside | B46: EBITDA margin % | C46: 0.46 | D46: 0.48 | E46: 0.49 | F46: 0.5 | G46: 0.505
A47: Upside | B47: D&A (% revenue) | C47: 0.26 | D47: 0.248 | E47: 0.235 | F47: 0.225 | G47: 0.22
A48: Upside | B48: CapEx (% revenue) | C48: 0.255 | D48: 0.21 | E48: 0.18 | F48: 0.16 | G48: 0.15
A49: Upside | B49: Change in NWC (% revenue) | C49: 0.005 | D49: 0.005 | E49: 0.005 | F49: 0.005 | G49: 0.005
...

Sheet Data_Raw
A1: Source Data & Provenance
A2: Controlled historical inputs | Source-backed values in green • Derived metrics in black • No illustrative valuation inputs on this tab
A4: HISTORICAL SOURCE DATA
A5: Metric | B5: FY2023A | C5: FY2024A | D5: FY2025A | E5: Unit | F5: Source document | G5: Source URL | H5: Notes | I5: Data status
A6: Revenue | B6: 2019 | C6: 2001 | D6: 2627 | E6: EURm | F6: SES FY2025 Results PDF / SES FY2024 Results Release | G6: https://www.ses.com/sites/default/files/2026-03/2603_FY2025%20Press%20Release_Final.pdf | H6: FY2025 reported revenue is €2,627m and includes Intelsat from 17 July 2025; the same official release presents FY2024 reported revenue of €2,001m. FY2023 remains the three-year comparison input. | I6: Verified against official SES sources on 19 August 2026.
A7: Adjusted EBITDA | B7: 1010 | C7: 1028 | D7: 1196 | E7: EURm | F7: SES FY2025 Results PDF / SES FY2024 Results Release | G7: https://www.ses.com/sites/default/files/2026-03/2603_FY2025%20Press%20Release_Final.pdf | H7: FY2025 reported Adjusted EBITDA is €1,196m; the same official release presents FY2024 reported Adjusted EBITDA of €1,028m. FY2023 remains the three-year comparison input. | I7: Verified against official SES sources on 19 August 2026.
A8: Adjusted EBITDA margin | B8: =B7/B6 -> 0.50024765 | C8: =C7/C6 -> 0.51374313 | D8: =D7/D6 -> 0.45527217 | E8: % | F8: Calculated from Revenue and Adjusted EBITDA | G8: n/a | H8: Live calculation; not a pasted source value. | I8: Derived
A9: Adjusted Net Debt / EBITDA | C9: 1.1 | D9: 3.9 | E9: x | F9: SES FY2025 Results / FY2024 Results | G9: https://www.ses.com/sites/default/files/2026-03/2603_FY2025%20Press%20Release_Final.pdf | H9: FY2025 combined like-for-like leverage; FY2023 is intentionally blank because no consistent model input is used. | I9: Verified against official SES sources on 19 August 2026.
A10: Adjusted Free Cash Flow | C10: 253 | D10: 229 | E10: EURm | F10: SES FY2025 Results / FY2024 Results | G10: https://www.ses.com/sites/default/files/2026-03/2603_FY2025%20Press%20Release_Final.pdf | H10: Included for context only; the valuation model uses its own FCFF construction. | I10: Verified against official SES sources on 19 August 2026.
A11: Capital Expenditure | C11: 560 | D11: 559 | E11: EURm | F11: SES FY2025 Results | G11: https://www.ses.com/sites/default/files/2026-03/2603_FY2025%20Press%20Release_Final.pdf | H11: Historical investment reference; forecast CapEx is driver-based in Assumptions. | I11: Verified against official SES sources on 19 August 2026.
A12: Completeness note: FY2023 leverage, Adjusted Free Cash Flow, and Capital Expenditure are intentionally unavailable in the controlled dataset; downstream Historicals displays these fields as n.a. rather than treating them as zero.
A14: KEY SOURCE-BACKED FACTS
A15: Fact | B15: Value | C15: Unit | D15: Effective date | E15: Source document | F15: Source URL | G15: Model use | H15: Data status | I15: Analyst note
A16: Intelsat acquisition completion | B16: Completed | C16: Event | D16: 45855 | E16: SES Intelsat Completion Release | F16: https://www.ses.com/press-release/ses-completes-acquisition-intelsat-creating-global-multi-orbit-connectivity | G16: Defines FY2025 as a transition/reporting-basis year. | H16: Source-backed | I16: Intelsat is consolidated from the closing date; FY2025 is not a clean organic-growth year.
A17: FY2026 outlook | B17: Stable year-on-year, like-for-like and constant FX | C17: Revenue outlook | D17: FY2026 | E17: SES FY2025 Results PDF | F17: https://www.ses.com/sites/default/files/2026-03/2603_FY2025%20Press%20Release_Final.pdf | G17: Anchors Base-case FY2026 revenue growth at 0.0%; the outlook applies to both Revenue and Adjusted EBITDA on a like-for-like, constant-FX basis. | H17: Source-backed | I17: The Base case follows management guidance; Upside and Downside cases deliberately test deviations from that outlook.
A18: Listing venues | B18: Euronext Paris / Luxembourg Stock Exchange | C18: Equity listing | D18: Current model basis | E18: SES shareholder information | F18: https://www.ses.com/investors/shareholder-information | G18: Confirms target identity and ticker context. | H18: Source-backed | I18: Ticker used in the cover and investment memo: SESG.
A19: Luxembourg City combined corporate tax rate | B19: 0.2387 | C19: % | D19: Tax year 2025+ | E19: PwC Luxembourg Corporate Tax Summary | F19: https://taxsummaries.pwc.com/luxembourg/corporate/taxes-on-corporate-income | G19: Simplifying tax proxy for forecast NOPAT and after-tax debt cost. | H19: Source-backed | I19: PwC reports a 23.87% combined rate for a Luxembourg City company in the top bracket: 16% corporate income tax, 1.12% solidarity surtax, and 6.75% municipal business tax. SES’s group effective rate remains multi-jurisdictional.
A23: DATA QUALITY CONTROLS
A24: Control | B24: Result | C24: Threshold / expectation | D24: Interpretation
A25: Revenue history complete | B25: =IF(COUNT(B6:D6)=3,"PASS","REVIEW") -> PASS | C25: 3 annual observations | D25: Supports the minimum three-year historical requirement.
A26: EBITDA history complete | B26: =IF(COUNT(B7:D7)=3,"PASS","REVIEW") -> PASS | C26: 3 annual observations | D26: Supports margin and growth diagnostics.
A27: Margins reconcile | B27: =IF(MAX(ABS(B8-B7/B6),ABS(C8-C7/C6),ABS(D8-D7/D6))<0.0001,"PASS","REVIEW") -> PASS | C27: Difference below 0.01 percentage points | D27: Confirms calculated margins are internally consistent.
A28: FY2025 leverage available | B28: =IF(D9>0,"PASS","REVIEW") -> PASS | C28: Positive sourced multiple | D28: Feeds the enterprise-to-equity valuation bridge.
A29: Source URLs populated | B29: =IF(COUNTIF(G6:G11,"https://*")>=5,"PASS","REVIEW") -> PASS | C29: At least five populated source rows | D29: Provides traceable source documentation inside the workbook.
A30: Primary source links verified | B30: =IF(COUNTIF(C34:C39,"Verified")=6,"PASS","REVIEW") -> PASS | C30: 6 requested official sources | D30: Confirms every requested source URL has been checked against its official live destination.
A32: VERIFIED PRIMARY SOURCE REGISTER
A33: Source | B33: Authority | C33: Verified status | D33: Verified date | E33: URL | F33: Dataset coverage | G33: Workbook use | H33: Refresh trigger | I33: Verification note
A34: SES FY2025 Results PDF | B34: SES S.A. | C34: Verified | D34: 2026-08-19T00:00:00.000Z | E34: https://www.ses.com/sites/default/files/2026-03/2603_FY2025%20Press%20Release_Final.pdf | F34: FY2025 revenue €2,627m; Adjusted EBITDA €1,196m; reported-basis consolidation from 17 July 2025; FY2026 stable outlook; leverage and CapEx context. | G34: Primary historical dataset, outlook anchor, and valuation bridge. | H34: On publication of newer full-year results. | I34: Direct official PDF resolves and matches the model’s reported figures.
A35: SES FY2024 Results Press Release | B35: SES S.A. | C35: Verified | D35: 2026-08-19T00:00:00.000Z | E35: https://www.ses.com/press-release/ses-full-year-2024-results | F35: FY2024 revenue €2,001m; Adjusted EBITDA €1,028m; net leverage 1.1x; backlog and transaction context. | G35: Historical cross-check and pre-transaction operating context. | H35: On restatement or superseding filing. | I35: Official SES release resolves and supports the FY2024 values used.
A36: SES Financial Results Hub | B36: SES S.A. | C36: Verified | D36: 2026-08-19T00:00:00.000Z | E36: https://www.ses.com/investors/financial-results | F36: Official statements, press releases, presentations, and transcripts by reporting period. | G36: Document-discovery hub and refresh workflow. | H36: At each quarterly or annual reporting event. | I36: Official hub resolves and includes FY2025, FY2024, and earlier reporting periods.
A37: SES Annual Reports | B37: SES S.A. | C37: Verified | D37: 2026-08-19T00:00:00.000Z | E37: https://www.ses.com/investors/annual-reports | F37: 2025 Annual Report, responsibility statement, official iXBRL, and report archive. | G37: Cap-table, minorities, accounting policies, and disclosure refresh. | H37: When a new annual report or filing is published. | I37: Official annual-report hub resolves and displays the 2025 Annual Report.
A38: SES Intelsat Completion Release | B38: SES S.A. | C38: Verified | D38: 2026-08-19T00:00:00.000Z | E38: https://www.ses.com/press-release/ses-completes-acquisition-intelsat-creating-global-multi-orbit-connectivity | F38: Confirms acquisition completion on 17 July 2025 and strategic transaction context. | G38: Defines the FY2025 consolidation boundary and transition-year interpretation. | H38: Only if transaction disclosures are subsequently corrected. | I38: Official SES release resolves and confirms the completion date.
A39: PwC Luxembourg Corporate Tax Summary | B39: PwC Worldwide Tax Summaries | C39: Verified | D39: 2026-08-19T00:00:00.000Z | E39: https://taxsummaries.pwc.com/luxembourg/corporate/taxes-on-corporate-income | F39: Luxembourg City combined corporate income tax rate of 23.87% for the top bracket from 2025. | G39: Forecast tax proxy and after-tax cost-of-debt calculation. | H39: When Luxembourg tax legislation or municipal rates change. | I39: Live PwC page was last reviewed 31 July 2026 and supports the 23.87% rate.

Sheet Historicals
A1: Historical Performance & Diagnostics
A2: Three-year reported performance linked to verified source data | EUR millions unless stated otherwise
A4: HISTORICAL OPERATING PERFORMANCE
A5: Metric | B5: FY2023A | C5: FY2024A | D5: FY2025A | E5: Trend diagnostic | F5: Data status | G5: Analyst interpretation
A6: Revenue | B6: =Data_Raw!B6 -> 2019 | C6: =Data_Raw!C6 -> 2001 | D6: =Data_Raw!D6 -> 2627 | E6: =(D6/B6)^(1/2)-1 -> 0.14067488 | F6: =IF(Data_Raw!I6="Derived","Calculated","Source-linked") -> Source-linked | G6: Reported revenue increased sharply in FY2025, but the acquisition-driven consolidation means this is not comparable organic growth.
A7: Adjusted EBITDA | B7: =Data_Raw!B7 -> 1010 | C7: =Data_Raw!C7 -> 1028 | D7: =Data_Raw!D7 -> 1196 | E7: =(D7/B7)^(1/2)-1 -> 0.088190432 | F7: =IF(Data_Raw!I7="Derived","Calculated","Source-linked") -> Source-linked | G7: Reported EBITDA increased less quickly than revenue, indicating material dilution in the combined-company margin.
A8: Adjusted EBITDA margin | B8: =Data_Raw!B8 -> 0.50024765 | C8: =Data_Raw!C8 -> 0.51374313 | D8: =Data_Raw!D8 -> 0.45527217 | E8: =(D8-C8)*100 -> -5.8470955 | F8: =IF(Data_Raw!I8="Derived","Calculated","Source-linked") -> Calculated | G8: The FY2025 margin reset is the central operating debate; the forecast assumes gradual recovery rather than an immediate return to 51%+.
A9: Adjusted Net Debt / EBITDA | B9: =IF(Data_Raw!B9="","n.a.",Data_Raw!B9) -> n.a. | C9: =IF(Data_Raw!C9="","n.a.",Data_Raw!C9) -> 1.1 | D9: =IF(Data_Raw!D9="","n.a.",Data_Raw!D9) -> 3.9 | E9: =D9-C9 -> 2.8 | F9: =IF(Data_Raw!I9="Derived","Calculated","Source-linked") -> Source-linked | G9: Leverage rose after the Intelsat transaction; valuation therefore uses a target capital structure and explicitly highlights deleveraging risk.
A10: Adjusted Free Cash Flow | B10: =IF(Data_Raw!B10="","n.a.",Data_Raw!B10) -> n.a. | C10: =IF(Data_Raw!C10="","n.a.",Data_Raw!C10) -> 253 | D10: =IF(Data_Raw!D10="","n.a.",Data_Raw!D10) -> 229 | E10: =D10/C10-1 -> -0.09486166 | F10: =IF(Data_Raw!I10="Derived","Calculated","Source-linked") -> Source-linked | G10: Adjusted FCF declined year-on-year despite higher reported EBITDA, underscoring integration and investment demands.
A11: Capital Expenditure | B11: =IF(Data_Raw!B11="","n.a.",Data_Raw!B11) -> n.a. | C11: =IF(Data_Raw!C11="","n.a.",Data_Raw!C11) -> 560 | D11: =IF(Data_Raw!D11="","n.a.",Data_Raw!D11) -> 559 | E11: =D11/C11-1 -> -0.0017857143 | F11: =IF(Data_Raw!I11="Derived","Calculated","Source-linked") -> Source-linked | G11: Capital expenditure remained broadly flat at an elevated level, consistent with a capital-intensive satellite infrastructure model.
A14: KEY HISTORICAL DIAGNOSTICS
A15: Reported revenue growth | C15: =D6/C6-1 -> 0.31284358 | E15: FY2025 versus FY2024, reported basis; acquisition consolidation is the main driver.
A16: Reported EBITDA growth | C16: =D7/C7-1 -> 0.16342412 | E16: FY2025 versus FY2024, reported basis; growth lagged revenue as the blended margin compressed.
A17: EBITDA margin change | C17: =(D8-C8)*100 -> -5.8470955 | E17: FY2025 versus FY2024; the decline captures mix dilution and transition effects.
A18: Leverage change | C18: =D9-C9 -> 2.8 | E18: FY2025 versus FY2024; the post-transaction balance sheet carries materially greater financial risk.
A21: STORY IN BRIEF
A22: ="FY2025 marks a structural break rather than a normal trend year. Reported revenue rose "&TEXT(C15,"0.0%")&" and Adjusted EBITDA rose "&TEXT(C16,"0.0%")&" versus FY2024, primarily because Intelsat was consolidated from 17 July 2025. However, the EBITDA margin fell by "&TEXT(ABS(C17),"0.0")&" percentage points to "&TEXT(D8,"0.0%")&", while leverage increased by "&TEXT(C18,"0.0x")&" to "&TEXT(D9,"0.0x")&". The model therefore treats FY2025 as the combined-company launch point and makes margin recovery, cash conversion, and deleveraging the core valuation tests." -> FY2025 marks a structural break rather than a normal trend year. Reported revenue rose 31.3% and Adjusted EBITDA rose 16.3% versus FY2024, primarily because Intelsat was consolidated from 17 July 2025. However, the EBITDA margin fell by 5.8 percentage points to 45.5%, while leverage increased by 2.8x to 3.9x. The model therefore treats FY2025 as the combined-company launch point and makes margin recovery, cash conversion, and deleveraging the core valuation tests.
A27: MODELLING IMPLICATION
A28: Do not extrapolate the FY2023–FY2025 reported revenue CAGR as an organic run rate. The forecast instead begins with management’s stable FY2026 outlook, assumes a gradual recovery in EBITDA margin, and retains explicit sensitivity to discount-rate and terminal-growth uncertainty.

Sheet Projections
A1: Five-Year Operating Projection
A2: Selected-case forecast | FY2026E–FY2030E | Live drivers from Assumptions | EUR millions unless stated otherwise
A4: FORECAST INCOME STATEMENT & FCFF BUILD
A5: Metric | B5: FY2026E | C5: FY2027E | D5: FY2028E | E5: FY2029E | F5: FY2030E | G5: Formula logic / valuation relevance
A6: Revenue | B6: =Data_Raw!D6*(1+Assumptions!B15) -> 2627 | C6: =B6*(1+Assumptions!C15) -> 2666.405 | D6: =C6*(1+Assumptions!D15) -> 2719.7331 | E6: =D6*(1+Assumptions!E15) -> 2787.7264 | F6: =E6*(1+Assumptions!F15) -> 2857.4196 | G6: Prior-year revenue × (1 + selected-case growth). FY2026 begins from FY2025 reported revenue.
A7: Revenue growth | B7: =Assumptions!B15 -> 0 | C7: =Assumptions!C15 -> 0.015 | D7: =Assumptions!D15 -> 0.02 | E7: =Assumptions!E15 -> 0.025 | F7: =Assumptions!F15 -> 0.025 | G7: Scenario-selected growth; Base case starts at 0.0% in line with management’s stable FY2026 outlook.
A8: Adjusted EBITDA | B8: =B6*Assumptions!B16 -> 1195.285 | C8: =C6*Assumptions!C16 -> 1253.2103 | D8: =D6*Assumptions!D16 -> 1305.4719 | E8: =E6*Assumptions!E16 -> 1352.0473 | F8: =F6*Assumptions!F16 -> 1400.1356 | G8: Revenue × selected-case EBITDA margin.
A9: EBITDA margin | B9: =Assumptions!B16 -> 0.455 | C9: =Assumptions!C16 -> 0.47 | D9: =Assumptions!D16 -> 0.48 | E9: =Assumptions!E16 -> 0.485 | F9: =Assumptions!F16 -> 0.49 | G9: Gradual recovery tests Intelsat integration and synergy delivery.
A10: D&A | B10: =-B6*Assumptions!B17 -> -683.02 | C10: =-C6*Assumptions!C17 -> -666.60125 | D10: =-D6*Assumptions!D17 -> -652.73594 | E10: =-E6*Assumptions!E17 -> -641.17708 | F10: =-F6*Assumptions!F17 -> -642.91941 | G10: Revenue × D&A assumption; shown as a deduction above EBIT.
A11: D&A as % of revenue | B11: =Assumptions!B17 -> 0.26 | C11: =Assumptions!C17 -> 0.25 | D11: =Assumptions!D17 -> 0.24 | E11: =Assumptions!E17 -> 0.23 | F11: =Assumptions!F17 -> 0.225 | G11: Purchase-price accounting and satellite depreciation taper gradually.
A12: EBIT | B12: =B8+B10 -> 512.265 | C12: =C8+C10 -> 586.6091 | D12: =D8+D10 -> 652.73594 | E12: =E8+E10 -> 710.87024 | F12: =F8+F10 -> 757.21619 | G12: Adjusted EBITDA less D&A.
A13: Tax on EBIT | B13: =-B12*Assumptions!B20 -> -122.27766 | C13: =-C12*Assumptions!C20 -> -140.02359 | D13: =-D12*Assumptions!D20 -> -155.80807 | E13: =-E12*Assumptions!E20 -> -169.68473 | F13: =-F12*Assumptions!F20 -> -180.7475 | G13: EBIT × Luxembourg tax proxy; actual group tax spans jurisdictions.
A14: NOPAT | B14: =B12+B13 -> 389.98734 | C14: =C12+C13 -> 446.58551 | D14: =D12+D13 -> 496.92787 | E14: =E12+E13 -> 541.18551 | F14: =F12+F13 -> 576.46869 | G14: After-tax operating profit available before reinvestment.
A15: Add: D&A | B15: =-B10 -> 683.02 | C15: =-C10 -> 666.60125 | D15: =-D10 -> 652.73594 | E15: =-E10 -> 641.17708 | F15: =-F10 -> 642.91941 | G15: Non-cash D&A is added back in the FCFF bridge.
A16: Less: Capital expenditure | B16: =-B6*Assumptions!B18 -> -693.528 | C16: =-C6*Assumptions!C18 -> -586.6091 | D16: =-D6*Assumptions!D18 -> -516.74929 | E16: =-E6*Assumptions!E18 -> -473.91349 | F16: =-F6*Assumptions!F18 -> -457.18713 | G16: Capital-intensive reinvestment; major build activity normalises over time.
A17: Less: Change in NWC | B17: =-B6*Assumptions!B19 -> -13.135 | C17: =-C6*Assumptions!C19 -> -13.332025 | D17: =-D6*Assumptions!D19 -> -13.598665 | E17: =-E6*Assumptions!E19 -> -13.938632 | F17: =-F6*Assumptions!F19 -> -14.287098 | G17: Modest working-capital investment linked to revenue.
A18: FCFF | B18: =B14+B15+B16+B17 -> 366.34434 | C18: =C14+C15+C16+C17 -> 513.24563 | D18: =D14+D15+D16+D17 -> 619.31586 | E18: =E14+E15+E16+E17 -> 694.51047 | F18: =F14+F15+F16+F17 -> 747.91386 | G18: Unlevered cash flow discounted in the DCF and used for terminal value.
A21: FORECAST DIAGNOSTICS
A22: Metric | B22: FY2026E | C22: FY2030E | D22: Change / CAGR
A23: Revenue | B23: =B6 -> 2627 | C23: =F6 -> 2857.4196 | D23: =(C23/B23)^(1/4)-1 -> 0.021241574 | E23: Low-single-digit revenue growth reflects a mature infrastructure profile rather than a high-growth case.
A24: Adjusted EBITDA | B24: =B8 -> 1195.285 | C24: =F8 -> 1400.1356 | D24: =(C24/B24)^(1/4)-1 -> 0.040338467 | E24: EBITDA growth outpaces revenue as the model assumes integration benefits and operating leverage.
A25: EBITDA margin | B25: =B9 -> 0.455 | C25: =F9 -> 0.49 | D25: =(C25-B25)*100 -> 3.5 | E25: Margin recovery is meaningful but remains below the 51.4% FY2024 standalone level.
A26: FCFF | B26: =B18 -> 366.34434 | C26: =F18 -> 747.91386 | D26: =(C26/B26)^(1/4)-1 -> 0.19533744 | E26: FCFF scales materially as margins recover and capital intensity normalises.
A27: FCFF margin | B27: =B18/B6 -> 0.1394535 | C27: =F18/F6 -> 0.2617445 | D27: =(C27-B27)*100 -> 12.2291 | E27: Cash conversion improves, reducing dependence on terminal-value assumptions over time.
A28: Capital expenditure / revenue | B28: =-B16/B6 -> 0.264 | C28: =-F16/F6 -> 0.16 | D28: =(C28-B28)*100 -> -10.4 | E28: CapEx intensity declines as IRIS², meoSphere, and major fleet investment phases mature.
A30: FORECAST STORY IN BRIEF
A31: ="The "&Assumptions!B5&" case holds FY2026 revenue at €"&TEXT(B6,"#,##0")&"m before growth resumes, reaching €"&TEXT(F6,"#,##0")&"m by FY2030. EBITDA margin expands from "&TEXT(B9,"0.0%")&" to "&TEXT(F9,"0.0%")&", while CapEx intensity falls from "&TEXT(-B16/B6,"0.0%")&" to "&TEXT(-F16/F6,"0.0%")&". These changes lift FCFF from €"&TEXT(B18,"#,##0")&"m to €"&TEXT(F18,"#,##0")&"m. The valuation therefore depends less on top-line acceleration than on disciplined integration, margin recovery, and capital normalisation." -> The Base case holds FY2026 revenue at €2,627m before growth resumes, reaching €2,857m by FY2030. EBITDA margin expands from 45.5% to 49.0%, while CapEx intensity falls from 26.4% to 16.0%. These changes lift FCFF from €366m to €748m. The valuation therefore depends less on top-line acceleration than on disciplined integration, margin recovery, and capital normalisation.
A36: MODEL INTEGRITY CHECKS
A37: Check | B37: Result | C37: Expectation
A38: Scenario drivers linked | B38: =IF(AND(B7=Assumptions!B15,C7=Assumptions!C15,D7=Assumptions!D15,E7=Assumptions!E15,F7=Assumptions!F15),"PASS","REVIEW") -> PASS | C38: All five annual drivers match the selected scenario.
A39: FCFF bridge balances | B39: =IF(MAX(ABS(B18-SUM(B14:B17)),ABS(C18-SUM(C14:C17)),ABS(D18-SUM(D14:D17)),ABS(E18-SUM(E14:E17)),ABS(F18-SUM(F14:F17)))<0.01,"PASS","REVIEW") -> PASS | C39: FCFF equals NOPAT + D&A − CapEx − change in NWC.
A40: Forecast periods complete | B40: =IF(COUNT(B6:F18)=65,"PASS","REVIEW") -> PASS | C40: All 65 numeric forecast cells are populated.
A41: Terminal-year WACC spread positive | B41: =IF(Assumptions!B7>Assumptions!B8,"PASS","REVIEW") -> PASS | C41: WACC must exceed terminal growth for a valid Gordon Growth calculation.

Sheet WACC
A1: Weighted Average Cost of Capital
A2: Bottom-up beta and target-capital-structure approach | Refreshable market inputs are explicitly identified
A3: Market Data Observation Date | B3: =DATE(2026,8,19) -> 46253 | C3: All market-sensitive inputs must be aligned to this observation date; less-frequent published series use the latest available data as of that date.
A4: COST OF EQUITY — CAPM PLUS EXECUTION-RISK PREMIUM
A5: Risk-free rate — German Bund reference proxy (Aug-2032 maturity) | B5: 0.0299 | C5: Market-based EUR input as of 18 August 2026: 2.99% yield on the 1.70% German Federal bond maturing 15 August 2032 (ISIN DE0001102606). This is a liquid Bund reference proxy with approximately six years remaining, not a constant-maturity 10-year yield. Deutsche Bundesbank reference-price data via Deutsche Finanzagentur.
A6: Mature-market equity risk premium | B6: 0.0423 | C6: Market-based mature-market proxy: Damodaran’s 4.23% implied equity risk premium, January 2026 update.
A7: Company-specific risk premium | B7: 0.01 | C7: Analyst judgement for Intelsat integration, cash conversion, and deleveraging execution risk.
A8: Target Debt / Value | B8: 0.35 | C8: Target structure used for valuation; avoids mechanically capitalising temporary post-transaction leverage.
A9: Target Equity / Value | B9: =1-B8 -> 0.65 | C9: Formula: 1 − target Debt / Value.
A10: Tax rate | B10: 0.2387 | C10: Source-linked Luxembourg City top-bracket proxy; SES’s effective rate spans several jurisdictions.
A13: BOTTOM-UP BETA
A14: Peer | B14: Levered beta | C14: Debt / Equity | D14: Tax rate | E14: Unlevered beta | F14: Input status | G14: Refresh note
A15: Eutelsat Communications | B15: 1.15 | C15: 0.85 | D15: 0.25 | E15: =B15/(1+(1-D15)*C15) -> 0.70229008 | F15: Illustrative | G15: Refresh beta, market equity, debt, and marginal tax rate from Bloomberg, Capital IQ, FactSet, or current filings.
A16: Iridium Communications | B16: 0.95 | C16: 0.15 | D16: 0.21 | E16: =B16/(1+(1-D16)*C16) -> 0.84935181 | F16: Illustrative | G16: Refresh beta, market equity, debt, and marginal tax rate from Bloomberg, Capital IQ, FactSet, or current filings.
A17: Viasat Inc. | B17: 1.3 | C17: 1.2 | D17: 0.21 | E17: =B17/(1+(1-D17)*C17) -> 0.66735113 | F17: Illustrative | G17: Refresh beta, market equity, debt, and marginal tax rate from Bloomberg, Capital IQ, FactSet, or current filings.
A18: Telesat Corporation | B18: 1.4 | C18: 2 | D18: 0.265 | E18: =B18/(1+(1-D18)*C18) -> 0.56680162 | F18: Illustrative | G18: Refresh beta, market equity, debt, and marginal tax rate from Bloomberg, Capital IQ, FactSet, or current filings.
A19: EchoStar Corporation | B19: 1.05 | C19: 0.9 | D19: 0.21 | E19: =B19/(1+(1-D19)*C19) -> 0.61367621 | F19: Illustrative | G19: Refresh beta, market equity, debt, and marginal tax rate from Bloomberg, Capital IQ, FactSet, or current filings.
A21: Average unlevered beta | E21: =AVERAGE(E15:E19) -> 0.67989417 | F21: Formula
A22: Target Debt / Equity | E22: =B8/B9 -> 0.53846154 | F22: Formula
A23: Relevered beta | E23: =E21*(1+(1-B10)*E22) -> 0.95860371 | F23: Formula
A24: Cost of equity | E24: =B5+E23*B6+B7 -> 0.080448937 | F24: Formula
A26: COST OF DEBT & WACC RECONCILIATION
A27: Pre-tax cost of debt | B27: 0.043 | C27: Illustrative debt-cost input. Refresh using SES’s observable EUR bond yields / credit spread and current debt mix.
A28: After-tax cost of debt | B28: =B27*(1-B10) -> 0.0327359 | C28: Formula: pre-tax cost of debt × (1 − tax rate).
A29: Calculated WACC | B29: =B9*E24+B8*B28 -> 0.063749374 | C29: Formula: Equity / Value × cost of equity + Debt / Value × after-tax cost of debt.
A30: Primary valuation WACC used in DCF | B30: =Assumptions!B7 -> 0.072 | C30: Selected scenario WACC. The Base case rounds above the mechanical calculation to reflect input uncertainty.
A33: WEIGHTED COMPONENT BRIDGE
A34: Equity weight | B34: =B9 -> 0.65 | C34: ="Equity contribution to WACC: "&TEXT(B34*B35,"0.00%") -> Equity contribution to WACC: 5.23%
A35: Cost of equity | B35: =E24 -> 0.080448937 | C35: CAPM plus company-specific risk premium.
A36: Debt weight | B36: =B8 -> 0.35 | C36: ="Debt contribution to WACC: "&TEXT(B36*B37,"0.00%") -> Debt contribution to WACC: 1.15%
A37: After-tax cost of debt | B37: =B28 -> 0.0327359 | C37: Tax shield applied to the illustrative pre-tax debt cost.
A39: METHODOLOGY & INVESTMENT INTERPRETATION
A40: Bottom-up beta | C40: Peer levered betas are unlevered using each peer’s D/E and tax rate, averaged, then relevered to SES’s target D/E.
A41: Target capital structure | C41: A 35% debt / 65% equity target reflects a normalised valuation structure rather than the temporary post-acquisition balance sheet.
A42: Selected WACC | C42: The primary 7.2% Base-case WACC is 0.8 percentage points above the refreshed mechanical result, providing a conservative buffer for beta, credit-spread, integration, and capital-structure uncertainty.
A43: Key limitation | C43: The risk-free rate and ERP are now source-based snapshots, but peer betas, D/E ratios, company-specific premium, and pre-tax debt cost remain refreshable modelling inputs.
A46: MODEL INTEGRITY & REFRESH CONTROLS
A47: Control | B47: Result | C47: Expectation
A48: Capital weights sum to 100% | B48: =IF(ABS(B8+B9-1)<0.0001,"PASS","REVIEW") -> PASS | C48: Debt / Value plus Equity / Value equals 100%. | E48: Input classification | F48: As-of / status | G48: Source
A49: Peer beta formulas complete | B49: =IF(COUNT(E15:E19)=5,"PASS","REVIEW") -> PASS | C49: All five peer unlevered betas calculate numerically. | E49: Risk-free rate | F49: 46252 | G49: German Federal bond / Bundesbank reference data
...

Sheet DCF
A1: Discounted Cash Flow Valuation
A2: FCFF-based enterprise valuation | Gordon Growth terminal value | Selected-case assumptions | EUR millions unless stated otherwise
A4: DCF OUTPUT SUMMARY
A5: WACC | B5: =Assumptions!B7 -> 0.072 | C5: Selected scenario discount rate from Assumptions.
A6: Terminal growth | B6: =Assumptions!B8 -> 0.015 | C6: Selected scenario long-term nominal FCFF growth rate.
A7: PV of explicit FCFF | B7: =SUM(B23:F23) -> 2345.2707 | C7: Present value of FY2026E–FY2030E FCFF.
A8: PV of terminal value | B8: =B30 -> 9407.3834 | C8: Present value of the Gordon Growth terminal value.
A9: Enterprise value | B9: =B7+B8 -> 11752.654 | C9: Enterprise value before net debt and minority interests.
A10: Less: Adjusted net debt | B10: =Assumptions!B24*Assumptions!B25 -> 4664.4 | C10: FY2025 leverage × FY2025 Adjusted EBITDA; source-linked inputs.
A11: Less: Minority interests | B11: =Assumptions!B26 -> 91 | C11: FY2025 reported non-controlling interests from the SES Annual Report.
A12: Equity value | B12: =B9-B10-B11 -> 6997.254 | C12: Enterprise value less adjusted net debt and reported minority interests.
A13: Diluted economic-equivalent shares | B13: =Assumptions!B27 -> 417.00622 | C13: Official SES economic-equivalent share count at 30 June 2026; fully diluted EPS is not materially different from basic EPS.
A14: Implied value per share | B14: =B12/B13 -> 16.779735 | C14: Indicative value per A-share/FDR using the source-based economic-equivalent share count.
A15: ENTERPRISE VALUE → EQUITY VALUE BRIDGE
A16: Enterprise Value | B16: Less: Net Debt | C16: Less: Minorities | D16: Equity Value
A17: =B9 -> 11752.654 | B17: =-B10 -> -4664.4 | C17: =-B11 -> -91 | D17: =B12 -> 6997.254
A18: Source-based equity bridge: FY2025 reported non-controlling interests and the latest official economic-equivalent share count are used.
A19: DISCOUNTED FCFF FORECAST
A20: Metric | B20: FY2026E | C20: FY2027E | D20: FY2028E | E20: FY2029E | F20: FY2030E | G20: Formula logic
A21: FCFF | B21: =Projections!B18 -> 366.34434 | C21: =Projections!C18 -> 513.24563 | D21: =Projections!D18 -> 619.31586 | E21: =Projections!E18 -> 694.51047 | F21: =Projections!F18 -> 747.91386 | G21: Linked from the selected-case projection.
A22: Discount factor | B22: =1/(1+$B$5)^1 -> 0.93283582 | C22: =1/(1+$B$5)^2 -> 0.87018267 | D22: =1/(1+$B$5)^3 -> 0.81173756 | E22: =1/(1+$B$5)^4 -> 0.75721788 | F22: =1/(1+$B$5)^5 -> 0.70635996 | G22: 1 ÷ (1 + WACC)^year.
A23: PV of FCFF | B23: =B21*B22 -> 341.73913 | C23: =C21*C22 -> 446.61745 | D23: =D21*D22 -> 502.72195 | E23: =E21*E22 -> 525.89574 | F23: =F21*F22 -> 528.29641 | G23: FCFF × discount factor.
A26: TERMINAL VALUE
A27: Terminal FCFF | B27: =F21*(1+$B$6) -> 759.13257 | C27: FY2030 FCFF × (1 + terminal growth).
A28: Terminal value at FY2030 | B28: =B27/($B$5-$B$6) -> 13318.115 | C28: Terminal FCFF ÷ (WACC − terminal growth).
A29: Terminal discount factor | B29: =F22 -> 0.70635996 | C29: FY2030 discount factor, carried from the explicit forecast.
A30: PV of terminal value | B30: =B28*B29 -> 9407.3834 | C30: Terminal value × terminal discount factor.
A31: Terminal value as % of EV | B31: =B30/B9 -> 0.80044757 | C31: Measures dependence on cash flows beyond the explicit forecast period.
A34: VALUATION DIAGNOSTICS
A35: Diagnostic | B35: Value | C35: Interpretation
A36: Explicit FCFF contribution | B36: =B7/B9 -> 0.19955243 | C36: Only the first five forecast years; the remaining value is captured in the terminal period.
A37: Terminal value contribution | B37: =B8/B9 -> 0.80044757 | C37: High, but consistent with a long-duration, low-growth infrastructure asset; sensitivity is therefore essential.
A38: Net debt and minorities / EV | B38: =(B10+B11)/B9 -> 0.4046235 | C38: Shows how post-transaction leverage materially reduces enterprise value available to equity holders.
A39: WACC less terminal growth | B39: =B5-B6 -> 0.057 | C39: A positive spread is required for the Gordon Growth formula; smaller spreads increase valuation sensitivity.
A41: VALUATION STORY IN BRIEF
A42: ="The "&Assumptions!B5&"-case DCF values SES at €"&TEXT(B9/1000,"0.0")&"bn of enterprise value and €"&TEXT(B12/1000,"0.0")&"bn of equity value. The source-based indicative per-share value is €"&TEXT(B14,"0.00")&". Terminal value contributes "&TEXT(B31,"0%")&" of enterprise value, so the result is highly sensitive to the "&TEXT(B5,"0.0%")&" WACC and "&TEXT(B6,"0.0%")&" terminal-growth assumptions. Adjusted net debt and minorities absorb "&TEXT((B10+B11)/B9,"0%")&" of enterprise value, making deleveraging a central equity-value catalyst." -> The Base-case DCF values SES at €11.8bn of enterprise value and €7.0bn of equity value. The source-based indicative per-share value is €16.78. Terminal value contributes 80% of enterprise value, so the result is highly sensitive to the 7.2% WACC and 1.5% terminal-growth assumptions. Adjusted net debt and minorities absorb 40% of enterprise value, making deleveraging a central equity-value catalyst.
A47: MODEL INTEGRITY & JUDGEMENT CONTROLS
A48: Control | B48: Result | C48: Expectation
A49: WACC exceeds terminal growth | B49: =IF(B5>B6,"PASS","REVIEW") -> PASS | C49: Required for a mathematically valid Gordon Growth terminal value.
A50: Explicit FCFF links complete | B50: =IF(COUNT(B21:F21)=5,"PASS","REVIEW") -> PASS | C50: Five years of FCFF are linked from Projections.
...

Sheet Sensitivity
A1: DCF Sensitivity Analysis
A2: Two-variable analysis of WACC and terminal growth | Enterprise value and indicative equity value per share
A4: ENTERPRISE VALUE SENSITIVITY (€m)
A5: WACC Terminal growth | B5: 0.005 | C5: 0.01 | D5: 0.015 | E5: 0.02 | F5: 0.025 | G5: WACC interpretation
A6: 0.062 | B6: =SUM(Projections!B18/(1+$A6)^1,Projections!C18/(1+$A6)^2,Projections!D18/(1+$A6)^3,Projections!E18/(1+$A6)^4,Projections!F18/(1+$A6)^5)+(Projections!F18*(1+B$5)/($A6-B$5))/(1+$A6)^5 -> 12178.291 | C6: =SUM(Projections!B18/(1+$A6)^1,Projections!C18/(1+$A6)^2,Projections!D18/(1+$A6)^3,Projections!E18/(1+$A6)^4,Projections!F18/(1+$A6)^5)+(Projections!F18*(1+C$5)/($A6-C$5))/(1+$A6)^5 -> 13170.14 | D6: =SUM(Projections!B18/(1+$A6)^1,Projections!C18/(1+$A6)^2,Projections!D18/(1+$A6)^3,Projections!E18/(1+$A6)^4,Projections!F18/(1+$A6)^5)+(Projections!F18*(1+D$5)/($A6-D$5))/(1+$A6)^5 -> 14373.02 | E6: =SUM(Projections!B18/(1+$A6)^1,Projections!C18/(1+$A6)^2,Projections!D18/(1+$A6)^3,Projections!E18/(1+$A6)^4,Projections!F18/(1+$A6)^5)+(Projections!F18*(1+E$5)/($A6-E$5))/(1+$A6)^5 -> 15862.3 | F6: =SUM(Projections!B18/(1+$A6)^1,Projections!C18/(1+$A6)^2,Projections!D18/(1+$A6)^3,Projections!E18/(1+$A6)^4,Projections!F18/(1+$A6)^5)+(Projections!F18*(1+F$5)/($A6-F$5))/(1+$A6)^5 -> 17754.088 | G6: 6.2%: low discount-rate case; values are most exposed to terminal-growth optimism.
A7: 0.067 | B7: =SUM(Projections!B18/(1+$A7)^1,Projections!C18/(1+$A7)^2,Projections!D18/(1+$A7)^3,Projections!E18/(1+$A7)^4,Projections!F18/(1+$A7)^5)+(Projections!F18*(1+B$5)/($A7-B$5))/(1+$A7)^5 -> 11146.638 | C7: =SUM(Projections!B18/(1+$A7)^1,Projections!C18/(1+$A7)^2,Projections!D18/(1+$A7)^3,Projections!E18/(1+$A7)^4,Projections!F18/(1+$A7)^5)+(Projections!F18*(1+C$5)/($A7-C$5))/(1+$A7)^5 -> 11963.027 | D7: =SUM(Projections!B18/(1+$A7)^1,Projections!C18/(1+$A7)^2,Projections!D18/(1+$A7)^3,Projections!E18/(1+$A7)^4,Projections!F18/(1+$A7)^5)+(Projections!F18*(1+D$5)/($A7-D$5))/(1+$A7)^5 -> 12936.415 | E7: =SUM(Projections!B18/(1+$A7)^1,Projections!C18/(1+$A7)^2,Projections!D18/(1+$A7)^3,Projections!E18/(1+$A7)^4,Projections!F18/(1+$A7)^5)+(Projections!F18*(1+E$5)/($A7-E$5))/(1+$A7)^5 -> 14116.906 | F7: =SUM(Projections!B18/(1+$A7)^1,Projections!C18/(1+$A7)^2,Projections!D18/(1+$A7)^3,Projections!E18/(1+$A7)^4,Projections!F18/(1+$A7)^5)+(Projections!F18*(1+F$5)/($A7-F$5))/(1+$A7)^5 -> 15578.466 | G7: 6.7%: lower-risk case within the model’s sensitivity range.
A8: 0.072 | B8: =SUM(Projections!B18/(1+$A8)^1,Projections!C18/(1+$A8)^2,Projections!D18/(1+$A8)^3,Projections!E18/(1+$A8)^4,Projections!F18/(1+$A8)^5)+(Projections!F18*(1+B$5)/($A8-B$5))/(1+$A8)^5 -> 10269.717 | C8: =SUM(Projections!B18/(1+$A8)^1,Projections!C18/(1+$A8)^2,Projections!D18/(1+$A8)^3,Projections!E18/(1+$A8)^4,Projections!F18/(1+$A8)^5)+(Projections!F18*(1+C$5)/($A8-C$5))/(1+$A8)^5 -> 10951.39 | D8: =SUM(Projections!B18/(1+$A8)^1,Projections!C18/(1+$A8)^2,Projections!D18/(1+$A8)^3,Projections!E18/(1+$A8)^4,Projections!F18/(1+$A8)^5)+(Projections!F18*(1+D$5)/($A8-D$5))/(1+$A8)^5 -> 11752.654 | E8: =SUM(Projections!B18/(1+$A8)^1,Projections!C18/(1+$A8)^2,Projections!D18/(1+$A8)^3,Projections!E18/(1+$A8)^4,Projections!F18/(1+$A8)^5)+(Projections!F18*(1+E$5)/($A8-E$5))/(1+$A8)^5 -> 12708.008 | F8: =SUM(Projections!B18/(1+$A8)^1,Projections!C18/(1+$A8)^2,Projections!D18/(1+$A8)^3,Projections!E18/(1+$A8)^4,Projections!F18/(1+$A8)^5)+(Projections!F18*(1+F$5)/($A8-F$5))/(1+$A8)^5 -> 13866.628 | G8: 7.2%: selected Base-case WACC; the 1.5% column is the primary DCF point.
A9: 0.077 | B9: =SUM(Projections!B18/(1+$A9)^1,Projections!C18/(1+$A9)^2,Projections!D18/(1+$A9)^3,Projections!E18/(1+$A9)^4,Projections!F18/(1+$A9)^5)+(Projections!F18*(1+B$5)/($A9-B$5))/(1+$A9)^5 -> 9515.2759 | C9: =SUM(Projections!B18/(1+$A9)^1,Projections!C18/(1+$A9)^2,Projections!D18/(1+$A9)^3,Projections!E18/(1+$A9)^4,Projections!F18/(1+$A9)^5)+(Projections!F18*(1+C$5)/($A9-C$5))/(1+$A9)^5 -> 10091.447 | D9: =SUM(Projections!B18/(1+$A9)^1,Projections!C18/(1+$A9)^2,Projections!D18/(1+$A9)^3,Projections!E18/(1+$A9)^4,Projections!F18/(1+$A9)^5)+(Projections!F18*(1+D$5)/($A9-D$5))/(1+$A9)^5 -> 10760.549 | E9: =SUM(Projections!B18/(1+$A9)^1,Projections!C18/(1+$A9)^2,Projections!D18/(1+$A9)^3,Projections!E18/(1+$A9)^4,Projections!F18/(1+$A9)^5)+(Projections!F18*(1+E$5)/($A9-E$5))/(1+$A9)^5 -> 11547.037 | F9: =SUM(Projections!B18/(1+$A9)^1,Projections!C18/(1+$A9)^2,Projections!D18/(1+$A9)^3,Projections!E18/(1+$A9)^4,Projections!F18/(1+$A9)^5)+(Projections!F18*(1+F$5)/($A9-F$5))/(1+$A9)^5 -> 12484.773 | G9: 7.7%: execution-risk case used in the lower DCF football-field anchor.
A10: 0.082 | B10: =SUM(Projections!B18/(1+$A10)^1,Projections!C18/(1+$A10)^2,Projections!D18/(1+$A10)^3,Projections!E18/(1+$A10)^4,Projections!F18/(1+$A10)^5)+(Projections!F18*(1+B$5)/($A10-B$5))/(1+$A10)^5 -> 8859.4413 | C10: =SUM(Projections!B18/(1+$A10)^1,Projections!C18/(1+$A10)^2,Projections!D18/(1+$A10)^3,Projections!E18/(1+$A10)^4,Projections!F18/(1+$A10)^5)+(Projections!F18*(1+C$5)/($A10-C$5))/(1+$A10)^5 -> 9351.5821 | D10: =SUM(Projections!B18/(1+$A10)^1,Projections!C18/(1+$A10)^2,Projections!D18/(1+$A10)^3,Projections!E18/(1+$A10)^4,Projections!F18/(1+$A10)^5)+(Projections!F18*(1+D$5)/($A10-D$5))/(1+$A10)^5 -> 9917.1767 | E10: =SUM(Projections!B18/(1+$A10)^1,Projections!C18/(1+$A10)^2,Projections!D18/(1+$A10)^3,Projections!E18/(1+$A10)^4,Projections!F18/(1+$A10)^5)+(Projections!F18*(1+E$5)/($A10-E$5))/(1+$A10)^5 -> 10573.996 | F10: =SUM(Projections!B18/(1+$A10)^1,Projections!C18/(1+$A10)^2,Projections!D18/(1+$A10)^3,Projections!E18/(1+$A10)^4,Projections!F18/(1+$A10)^5)+(Projections!F18*(1+F$5)/($A10-F$5))/(1+$A10)^5 -> 11346.047 | G10: 8.2%: high discount-rate stress case.
A13: INDICATIVE EQUITY VALUE PER SHARE (€)
A14: WACC Terminal growth | B14: 0.005 | C14: 0.01 | D14: 0.015 | E14: 0.02 | F14: 0.025 | G14: Equity interpretation
A15: =A6 -> 0.062 | B15: =MAX((B6-DCF!$B$10-DCF!$B$11)/Assumptions!$B$27,0) -> 17.800433 | C15: =MAX((C6-DCF!$B$10-DCF!$B$11)/Assumptions!$B$27,0) -> 20.178931 | D15: =MAX((D6-DCF!$B$10-DCF!$B$11)/Assumptions!$B$27,0) -> 23.063492 | E15: =MAX((E6-DCF!$B$10-DCF!$B$11)/Assumptions!$B$27,0) -> 26.634854 | F15: =MAX((F6-DCF!$B$10-DCF!$B$11)/Assumptions!$B$27,0) -> 31.171448 | G15: Per-share sensitivity uses FY2025 reported minority interests and the official economic-equivalent share count.
A16: =A7 -> 0.067 | B16: =MAX((B7-DCF!$B$10-DCF!$B$11)/Assumptions!$B$27,0) -> 15.326481 | C16: =MAX((C7-DCF!$B$10-DCF!$B$11)/Assumptions!$B$27,0) -> 17.28422 | D16: =MAX((D7-DCF!$B$10-DCF!$B$11)/Assumptions!$B$27,0) -> 19.618448 | E16: =MAX((E7-DCF!$B$10-DCF!$B$11)/Assumptions!$B$27,0) -> 22.449319 | F16: =MAX((F7-DCF!$B$10-DCF!$B$11)/Assumptions!$B$27,0) -> 25.954208 | G16: Shows how lower discount rates amplify equity value after fixed debt deductions.
A17: =A8 -> 0.072 | B17: =MAX((B8-DCF!$B$10-DCF!$B$11)/Assumptions!$B$27,0) -> 13.223584 | C17: =MAX((C8-DCF!$B$10-DCF!$B$11)/Assumptions!$B$27,0) -> 14.858266 | D17: =MAX((D8-DCF!$B$10-DCF!$B$11)/Assumptions!$B$27,0) -> 16.779735 | E17: =MAX((E8-DCF!$B$10-DCF!$B$11)/Assumptions!$B$27,0) -> 19.070718 | F17: =MAX((F8-DCF!$B$10-DCF!$B$11)/Assumptions!$B$27,0) -> 21.849143 | G17: ="Base-case centre point equals the DCF’s €"&TEXT(DCF!B14,"0.00")&" per-share output." -> Base-case centre point equals the DCF’s €16.78 per-share output.
A18: =A9 -> 0.077 | B18: =MAX((B9-DCF!$B$10-DCF!$B$11)/Assumptions!$B$27,0) -> 11.4144 | C18: =MAX((C9-DCF!$B$10-DCF!$B$11)/Assumptions!$B$27,0) -> 12.796085 | D18: =MAX((D9-DCF!$B$10-DCF!$B$11)/Assumptions!$B$27,0) -> 14.400622 | E18: =MAX((E9-DCF!$B$10-DCF!$B$11)/Assumptions!$B$27,0) -> 16.286657 | F18: =MAX((F9-DCF!$B$10-DCF!$B$11)/Assumptions!$B$27,0) -> 18.535391 | G18: Higher WACC compresses equity value more sharply because debt remains fixed.
A19: =A10 -> 0.082 | B19: =MAX((B10-DCF!$B$10-DCF!$B$11)/Assumptions!$B$27,0) -> 9.8416789 | C19: =MAX((C10-DCF!$B$10-DCF!$B$11)/Assumptions!$B$27,0) -> 11.021855 | D19: =MAX((D10-DCF!$B$10-DCF!$B$11)/Assumptions!$B$27,0) -> 12.378177 | E19: =MAX((E10-DCF!$B$10-DCF!$B$11)/Assumptions!$B$27,0) -> 13.95326 | F19: =MAX((F10-DCF!$B$10-DCF!$B$11)/Assumptions!$B$27,0) -> 15.804674 | G19: Stress case highlights the downside asymmetry created by leverage.
A22: SENSITIVITY DIAGNOSTICS
A23: Diagnostic | B23: Value | C23: Unit / comparison | D23: Interpretation
A24: Base-case enterprise value | B24: =D8 -> 11752.654 | C24: Selected 7.2% WACC / 1.5% terminal growth | D24: The centre point reconciles directly to the DCF enterprise value.
A25: Full-grid EV range | B25: =MAX(B6:F10)-MIN(B6:F10) -> 8894.6465 | C25: Maximum minus minimum across all 25 EV cases | D25: The broad range demonstrates that terminal-value assumptions dominate apparent precision.
A26: Full-grid per-share range | B26: =MAX(B15:F19)-MIN(B15:F19) -> 21.329769 | C26: Maximum minus minimum across all 25 indicative share-price cases | D26: Leverage increases the sensitivity of equity value relative to enterprise value.
A27: +0.5 pp WACC impact at 1.5% g | B27: =D9/D8-1 -> -0.084415408 | C27: EV change from 7.2% to 7.7% WACC | D27: A modest increase in the discount rate causes a meaningful valuation decline.
A28: +0.5 pp terminal growth impact at 7.2% WACC | B28: =E8/D8-1 -> 0.081288347 | C28: EV change from 1.5% to 2.0% terminal growth | D28: A modest increase in terminal growth produces a material valuation uplift.
A30: READING THE SENSITIVITY
A31: ="The selected DCF point is €"&TEXT(D8/1000,"0.0")&"bn of enterprise value at a "&TEXT(A8,"0.0%")&" WACC and "&TEXT(D5,"0.0%")&" terminal growth rate. Across the full matrix, enterprise value ranges from €"&TEXT(MIN(B6:F10)/1000,"0.0")&"bn to €"&TEXT(MAX(B6:F10)/1000,"0.0")&"bn, while indicative equity value per share ranges from €"&TEXT(MIN(B15:F19),"0.00")&" to €"&TEXT(MAX(B15:F19),"0.00")&". At the Base terminal-growth rate, a 0.5 percentage-point increase in WACC reduces EV by "&TEXT(ABS(B27),"0.0%")&"; a 0.5 percentage-point increase in terminal growth raises EV by "&TEXT(B28,"0.0%")&". The model therefore presents valuation ranges rather than false precision." -> The selected DCF point is €11.8bn of enterprise value at a 7.2% WACC and 1.5% terminal growth rate. Across the full matrix, enterprise value ranges from €8.9bn to €17.8bn, while indicative equity value per share ranges from €9.84 to €31.17. At the Base terminal-growth rate, a 0.5 percentage-point increase in WACC reduces EV by 8.4%; a 0.5 percentage-point increase in terminal growth raises EV by 8.1%. The model therefore presents valuation ranges rather than false precision.
A37: MODEL INTEGRITY & RANGE CONTROLS
A38: Control | B38: Result | C38: Expectation | D38: Interpretation
A39: All EV cases valid | B39: =IF(COUNT(B6:F10)=25,"PASS","REVIEW") -> PASS | C39: All 25 enterprise-value cases calculate numerically. | D39: Formula completeness
